<?xml version="1.0" ?>
<!-- =================================================================================== -->
<!-- |    This document was autogenerated by xacro from C:/Users/Aeyoq/Documents/Droids/BD-X/A1/dev/BD-XURDFSimplifiedv2_description/urdf/BD-XURDFSimplifiedv2.xacro | -->
<!-- |    EDITING THIS FILE BY HAND IS NOT RECOMMENDED                                 | -->
<!-- =================================================================================== -->
<robot xmlns:xacro="http://www.ros.org/wiki/xacro" name="BD-XURDFSimplifiedv2">
  <material name="silver">
    <color rgba="0.700 0.700 0.700 1"/>
  </material>

      <!-- Dummy root link without inertia -->
  <link name="dummy_link"/>
  <!-- Fixed joint connecting base_link to sw_bd0 -->
  <joint name="fixed_base" type="fixed">
    <parent link="dummy_link"/>
    <child link="base_link"/>
    <origin xyz="0 0 0" rpy="0 0 0"/>
  </joint>

  <link name="base_link">
    <inertial>
      <origin xyz="0.0 0.0 0.0" rpy="0 0 0"/>
      <mass value="0.0"/>
      <inertia ixx="0.0" iyy="0.0" izz="0.0" ixy="0.0" iyz="0.0" ixz="0.0"/>
    </inertial>
    <visual>
      <origin xyz="0 0 0" rpy="0 0 0"/>
      <geometry>
        <mesh filename="package://bdx_description/meshes/base_link.stl" scale="0.001 0.001 0.001"/>
      </geometry>
      <material name="silver"/>
    </visual>
    <collision>
      <origin xyz="0 0 0" rpy="0 0 0"/>
      <geometry>
        <mesh filename="package://bdx_description/meshes/base_link.stl" scale="0.001 0.001 0.001"/>
      </geometry>
    </collision>
  </link>
  <link name="right_antenna">
    <inertial>
      <origin xyz="0.07855 -0.121396 -0.212607" rpy="0 0 0"/>
      <mass value="0.0"/>
      <inertia ixx="0.0" iyy="0.0" izz="0.0" ixy="0.0" iyz="0.0" ixz="0.0"/>
    </inertial>
    <visual>
      <origin xyz="0.07855 -0.121396 -0.212607" rpy="0 0 0"/>
      <geometry>
        <mesh filename="package://bdx_description/meshes/right_antenna.stl" scale="0.001 0.001 0.001"/>
      </geometry>
      <material name="silver"/>
    </visual>
    <collision>
      <origin xyz="0.07855 -0.121396 -0.212607" rpy="0 0 0"/>
      <geometry>
        <mesh filename="package://bdx_description/meshes/right_antenna.stl" scale="0.001 0.001 0.001"/>
      </geometry>
    </collision>
  </link>
  <link name="left_antenna">
    <inertial>
      <origin xyz="-0.07855 -0.121396 -0.212607" rpy="0 0 0"/>
      <mass value="0.0"/>
      <inertia ixx="0.0" iyy="0.0" izz="0.0" ixy="0.0" iyz="0.0" ixz="0.0"/>
    </inertial>
    <visual>
      <origin xyz="-0.07855 -0.121396 -0.212607" rpy="0 0 0"/>
      <geometry>
        <mesh filename="package://bdx_description/meshes/left_antenna.stl" scale="0.001 0.001 0.001"/>
      </geometry>
      <material name="silver"/>
    </visual>
    <collision>
      <origin xyz="-0.07855 -0.121396 -0.212607" rpy="0 0 0"/>
      <geometry>
        <mesh filename="package://bdx_description/meshes/left_antenna.stl" scale="0.001 0.001 0.001"/>
      </geometry>
    </collision>
  </link>
  <link name="head">
    <inertial>
      <origin xyz="0.0 0.029589 -0.13997" rpy="0 0 0"/>
      <mass value="0.0"/>
      <inertia ixx="0.0" iyy="0.0" izz="0.0" ixy="0.0" iyz="0.0" ixz="0.0"/>
    </inertial>
    <visual>
      <origin xyz="-0.0 0.029589 -0.13997" rpy="0 0 0"/>
      <geometry>
        <mesh filename="package://bdx_description/meshes/head.stl" scale="0.001 0.001 0.001"/>
      </geometry>
      <material name="silver"/>
    </visual>
    <collision>
      <origin xyz="-0.0 0.029589 -0.13997" rpy="0 0 0"/>
      <geometry>
        <mesh filename="package://bdx_description/meshes/head.stl" scale="0.001 0.001 0.001"/>
      </geometry>
    </collision>
  </link>
  <link name="neck_yaw">
    <inertial>
      <origin xyz="-1.1e-05 -0.025143 -0.142949" rpy="0 0 0"/>
      <mass value="0.0"/>
      <inertia ixx="0.0" iyy="0.0" izz="0.0" ixy="0.0" iyz="0.0" ixz="0.0"/>
    </inertial>
    <visual>
      <origin xyz="-1.1e-05 -0.025143 -0.142949" rpy="0 0 0"/>
      <geometry>
        <mesh filename="package://bdx_description/meshes/neck_yaw.stl" scale="0.001 0.001 0.001"/>
      </geometry>
      <material name="silver"/>
    </visual>
    <collision>
      <origin xyz="-1.1e-05 -0.025143 -0.142949" rpy="0 0 0"/>
      <geometry>
        <mesh filename="package://bdx_description/meshes/neck_yaw.stl" scale="0.001 0.001 0.001"/>
      </geometry>
    </collision>
  </link>
  <link name="neck_pitch">
    <inertial>
      <origin xyz="0.021882 -0.02779 -0.111051" rpy="0 0 0"/>
      <mass value="0.0"/>
      <inertia ixx="0.0" iyy="0.0" izz="0.0" ixy="0.0" iyz="0.0" ixz="0.0"/>
    </inertial>
    <visual>
      <origin xyz="0.021882 -0.02779 -0.111051" rpy="0 0 0"/>
      <geometry>
        <mesh filename="package://bdx_description/meshes/neck_pitch.stl" scale="0.001 0.001 0.001"/>
      </geometry>
      <material name="silver"/>
    </visual>
    <collision>
      <origin xyz="0.021882 -0.02779 -0.111051" rpy="0 0 0"/>
      <geometry>
        <mesh filename="package://bdx_description/meshes/neck_pitch.stl" scale="0.001 0.001 0.001"/>
      </geometry>
    </collision>
  </link>
  <link name="neck_extension">
    <inertial>
      <origin xyz="0.004148 0.097795 -0.060489" rpy="0 0 0"/>
      <mass value="0.0"/>
      <inertia ixx="0.0" iyy="0.0" izz="0.0" ixy="0.0" iyz="0.0" ixz="0.0"/>
    </inertial>
    <visual>
      <origin xyz="0.004148 0.097795 -0.060489" rpy="0 0 0"/>
      <geometry>
        <mesh filename="package://bdx_description/meshes/neck_extension.stl" scale="0.001 0.001 0.001"/>
      </geometry>
      <material name="silver"/>
    </visual>
    <collision>
      <origin xyz="0.004148 0.097795 -0.060489" rpy="0 0 0"/>
      <geometry>
        <mesh filename="package://bdx_description/meshes/neck_extension.stl" scale="0.001 0.001 0.001"/>
      </geometry>
    </collision>
  </link>
  <link name="left_foot">
    <inertial>
      <origin xyz="-0.123586 0.015986 0.294812" rpy="0 0 0"/>
      <mass value="0.0"/>
      <inertia ixx="0.0" iyy="0.0" izz="0.0" ixy="0.0" iyz="0.0" ixz="0.0"/>
    </inertial>
    <visual>
      <origin xyz="-0.123586 0.015986 0.294812" rpy="0 0 0"/>
      <geometry>
        <mesh filename="package://bdx_description/meshes/left_foot.stl" scale="0.001 0.001 0.001"/>
      </geometry>
      <material name="silver"/>
    </visual>
    <collision>
      <origin xyz="-0.123586 0.015986 0.294812" rpy="0 0 0"/>
      <geometry>
        <mesh filename="package://bdx_description/meshes/left_foot.stl" scale="0.001 0.001 0.001"/>
      </geometry>
    </collision>
  </link>
  <link name="left_lower_leg">
    <inertial>
      <origin xyz="-0.133053 0.016698 0.157628" rpy="0 0 0"/>
      <mass value="0.0"/>
      <inertia ixx="0.0" iyy="0.0" izz="0.0" ixy="0.0" iyz="0.0" ixz="0.0"/>
    </inertial>
    <visual>
      <origin xyz="-0.133053 0.016698 0.157628" rpy="0 0 0"/>
      <geometry>
        <mesh filename="package://bdx_description/meshes/left_lower_leg.stl" scale="0.001 0.001 0.001"/>
      </geometry>
      <material name="silver"/>
    </visual>
    <collision>
      <origin xyz="-0.133053 0.016698 0.157628" rpy="0 0 0"/>
      <geometry>
        <mesh filename="package://bdx_description/meshes/left_lower_leg.stl" scale="0.001 0.001 0.001"/>
      </geometry>
    </collision>
  </link>
  <link name="left_upper_leg">
    <inertial>
      <origin xyz="-0.133053 0.027291 0.039591" rpy="0 0 0"/>
      <mass value="0.0"/>
      <inertia ixx="0.0" iyy="0.0" izz="0.0" ixy="0.0" iyz="0.0" ixz="0.0"/>
    </inertial>
    <visual>
      <origin xyz="-0.133053 0.027291 0.039591" rpy="0 0 0"/>
      <geometry>
        <mesh filename="package://bdx_description/meshes/left_upper_leg.stl" scale="0.001 0.001 0.001"/>
      </geometry>
      <material name="silver"/>
    </visual>
    <collision>
      <origin xyz="-0.133053 0.027291 0.039591" rpy="0 0 0"/>
      <geometry>
        <mesh filename="package://bdx_description/meshes/left_upper_leg.stl" scale="0.001 0.001 0.001"/>
      </geometry>
    </collision>
  </link>
  <link name="left_hip">
    <inertial>
      <origin xyz="-0.051164 0.007949 0.037966" rpy="0 0 0"/>
      <mass value="0.0"/>
      <inertia ixx="0.0" iyy="0.0" izz="0.0" ixy="0.0" iyz="0.0" ixz="0.0"/>
    </inertial>
    <visual>
      <origin xyz="-0.051164 0.007949 0.037966" rpy="0 0 0"/>
      <geometry>
        <mesh filename="package://bdx_description/meshes/left_hip.stl" scale="0.001 0.001 0.001"/>
      </geometry>
      <material name="silver"/>
    </visual>
    <collision>
      <origin xyz="-0.051164 0.007949 0.037966" rpy="0 0 0"/>
      <geometry>
        <mesh filename="package://bdx_description/meshes/left_hip.stl" scale="0.001 0.001 0.001"/>
      </geometry>
    </collision>
  </link>
  <link name="left_hip_rotation">
    <inertial>
      <origin xyz="-0.046212 0.00171 -0.022391" rpy="0 0 0"/>
      <mass value="0.0"/>
      <inertia ixx="0.0" iyy="0.0" izz="0.0" ixy="0.0" iyz="0.0" ixz="0.0"/>
    </inertial>
    <visual>
      <origin xyz="-0.046212 0.00171 -0.022391" rpy="0 0 0"/>
      <geometry>
        <mesh filename="package://bdx_description/meshes/left_hip_rotation.stl" scale="0.001 0.001 0.001"/>
      </geometry>
      <material name="silver"/>
    </visual>
    <collision>
      <origin xyz="-0.046212 0.00171 -0.022391" rpy="0 0 0"/>
      <geometry>
        <mesh filename="package://bdx_description/meshes/left_hip_rotation.stl" scale="0.001 0.001 0.001"/>
      </geometry>
    </collision>
  </link>
  <link name="right_foot">
    <inertial>
      <origin xyz="0.124257 0.015977 0.294811" rpy="0 0 0"/>
      <mass value="0.0"/>
      <inertia ixx="0.0" iyy="0.0" izz="0.0" ixy="0.0" iyz="0.0" ixz="0.0"/>
    </inertial>
    <visual>
      <origin xyz="0.124257 0.015977 0.294811" rpy="0 0 0"/>
      <geometry>
        <mesh filename="package://bdx_description/meshes/right_foot.stl" scale="0.001 0.001 0.001"/>
      </geometry>
      <material name="silver"/>
    </visual>
    <collision>
      <origin xyz="0.124257 0.015977 0.294811" rpy="0 0 0"/>
      <geometry>
        <mesh filename="package://bdx_description/meshes/right_foot.stl" scale="0.001 0.001 0.001"/>
      </geometry>
    </collision>
  </link>
  <link name="right_lower_leg">
    <inertial>
      <origin xyz="0.133723 0.01669 0.157628" rpy="0 0 0"/>
      <mass value="0.0"/>
      <inertia ixx="0.0" iyy="0.0" izz="0.0" ixy="0.0" iyz="0.0" ixz="0.0"/>
    </inertial>
    <visual>
      <origin xyz="0.133723 0.01669 0.157628" rpy="0 0 0"/>
      <geometry>
        <mesh filename="package://bdx_description/meshes/right_lower_leg.stl" scale="0.001 0.001 0.001"/>
      </geometry>
      <material name="silver"/>
    </visual>
    <collision>
      <origin xyz="0.133723 0.01669 0.157628" rpy="0 0 0"/>
      <geometry>
        <mesh filename="package://bdx_description/meshes/right_lower_leg.stl" scale="0.001 0.001 0.001"/>
      </geometry>
    </collision>
  </link>
  <link name="right_upper_leg">
    <inertial>
      <origin xyz="0.133723 0.027282 0.03959" rpy="0 0 0"/>
      <mass value="0.0"/>
      <inertia ixx="0.0" iyy="0.0" izz="0.0" ixy="0.0" iyz="0.0" ixz="0.0"/>
    </inertial>
    <visual>
      <origin xyz="0.133723 0.027282 0.03959" rpy="0 0 0"/>
      <geometry>
        <mesh filename="package://bdx_description/meshes/right_upper_leg.stl" scale="0.001 0.001 0.001"/>
      </geometry>
      <material name="silver"/>
    </visual>
    <collision>
      <origin xyz="0.133723 0.027282 0.03959" rpy="0 0 0"/>
      <geometry>
        <mesh filename="package://bdx_description/meshes/right_upper_leg.stl" scale="0.001 0.001 0.001"/>
      </geometry>
    </collision>
  </link>
  <link name="right_hip">
    <inertial>
      <origin xyz="0.051835 0.00794 0.037965" rpy="0 0 0"/>
      <mass value="0.0"/>
      <inertia ixx="0.0" iyy="0.0" izz="0.0" ixy="0.0" iyz="0.0" ixz="0.0"/>
    </inertial>
    <visual>
      <origin xyz="0.051835 0.00794 0.037965" rpy="0 0 0"/>
      <geometry>
        <mesh filename="package://bdx_description/meshes/right_hip.stl" scale="0.001 0.001 0.001"/>
      </geometry>
      <material name="silver"/>
    </visual>
    <collision>
      <origin xyz="0.051835 0.00794 0.037965" rpy="0 0 0"/>
      <geometry>
        <mesh filename="package://bdx_description/meshes/right_hip.stl" scale="0.001 0.001 0.001"/>
      </geometry>
    </collision>
  </link>
  <link name="right_hip_rotation">
    <inertial>
      <origin xyz="0.046882 0.001702 -0.022392" rpy="0 0 0"/>
      <mass value="0.0"/>
      <inertia ixx="0.0" iyy="0.0" izz="0.0" ixy="0.0" iyz="0.0" ixz="0.0"/>
    </inertial>
    <visual>
      <origin xyz="0.046882 0.001702 -0.022392" rpy="0 0 0"/>
      <geometry>
        <mesh filename="package://bdx_description/meshes/right_hip_rotation.stl" scale="0.001 0.001 0.001"/>
      </geometry>
      <material name="silver"/>
    </visual>
    <collision>
      <origin xyz="0.046882 0.001702 -0.022392" rpy="0 0 0"/>
      <geometry>
        <mesh filename="package://bdx_description/meshes/right_hip_rotation.stl" scale="0.001 0.001 0.001"/>
      </geometry>
    </collision>
  </link>
  <link name="left_foot_pad">
    <inertial>
      <origin xyz="-0.10856 -0.047557 0.351528" rpy="0 0 0"/>
      <mass value="0.0"/>
      <inertia ixx="0.0" iyy="0.0" izz="0.0" ixy="0.0" iyz="0.0" ixz="0.0"/>
    </inertial>
    <visual>
      <origin xyz="-0.10856 -0.047557 0.351528" rpy="0 0 0"/>
      <geometry>
        <mesh filename="package://bdx_description/meshes/left_foot_pad.stl" scale="0.001 0.001 0.001"/>
      </geometry>
      <material name="silver"/>
    </visual>
    <collision>
      <origin xyz="-0.10856 -0.047557 0.351528" rpy="0 0 0"/>
      <geometry>
        <mesh filename="package://bdx_description/meshes/left_foot_pad.stl" scale="0.001 0.001 0.001"/>
      </geometry>
    </collision>
  </link>
  <link name="right_foot_pad">
    <inertial>
      <origin xyz="0.109231 -0.047566 0.351527" rpy="0 0 0"/>
      <mass value="0.0"/>
      <inertia ixx="0.0" iyy="0.0" izz="0.0" ixy="0.0" iyz="0.0" ixz="0.0"/>
    </inertial>
    <visual>
      <origin xyz="0.109231 -0.047566 0.351527" rpy="0 0 0"/>
      <geometry>
        <mesh filename="package://bdx_description/meshes/right_foot_pad.stl" scale="0.001 0.001 0.001"/>
      </geometry>
      <material name="silver"/>
    </visual>
    <collision>
      <origin xyz="0.109231 -0.047566 0.351527" rpy="0 0 0"/>
      <geometry>
        <mesh filename="package://bdx_description/meshes/right_foot_pad.stl" scale="0.001 0.001 0.001"/>
      </geometry>
    </collision>
  </link>
  <joint name="right_antenna" type="revolute">
    <origin xyz="-0.07855 0.150985 0.072637" rpy="0 0 0"/>
    <parent link="head"/>
    <child link="right_antenna"/>
    <axis xyz="-1.0 -0.0 -0.0"/>
    <limit upper="2.96706" lower="0.261799" effort="100.0" velocity="100.0"/>
  </joint>
  <joint name="left_antenna" type="revolute">
    <origin xyz="0.07855 0.150985 0.072637" rpy="0 0 0"/>
    <parent link="head"/>
    <child link="left_antenna"/>
    <axis xyz="1.0 0.0 -0.0"/>
    <limit upper="-0.261799" lower="-2.96706" effort="100.0" velocity="100.0"/>
  </joint>
  <joint name="head_roll" type="revolute">
    <origin xyz="-1.1e-05 -0.054732 -0.002979" rpy="0 0 0"/>
    <parent link="neck_yaw"/>
    <child link="head"/>
    <axis xyz="0.0 -0.95066 -0.310236"/>
    <limit upper="0.523599" lower="-0.523599" effort="100.0" velocity="100.0"/>
  </joint>
  <joint name="head_yaw" type="revolute">
    <origin xyz="0.021893 -0.002647 0.031898" rpy="0 0 0"/>
    <parent link="neck_pitch"/>
    <child link="neck_yaw"/>
    <axis xyz="0.0 -0.310236 0.95066"/>
    <limit upper="1.570796" lower="-1.570796" effort="100.0" velocity="100.0"/>
  </joint>
  <joint name="head_pitch" type="revolute">
    <origin xyz="-0.017734 0.125585 0.050562" rpy="0 0 0"/>
    <parent link="neck_extension"/>
    <child link="neck_pitch"/>
    <axis xyz="-1.0 -0.0 -0.0"/>
    <limit upper="1.570796" lower="0.0" effort="100.0" velocity="100.0"/>
  </joint>
  <joint name="neck_pitch" type="revolute">
    <origin xyz="-0.004148 -0.097795 0.060489" rpy="0 0 0"/>
    <parent link="base_link"/>
    <child link="neck_extension"/>
    <axis xyz="-1.0 -0.0 0.0"/>
    <limit upper="-0.087266" lower="-1.48353" effort="100.0" velocity="100.0"/>
  </joint>
  <joint name="left_ankle" type="revolute">
    <origin xyz="-0.009467 0.000712 -0.137184" rpy="0 0 0"/>
    <parent link="left_lower_leg"/>
    <child link="left_foot"/>
    <axis xyz="1.0 -0.0 -0.0"/>
    <limit upper="1.396263" lower="-1.22173" effort="100.0" velocity="100.0"/>
  </joint>
  <joint name="left_knee" type="revolute">
    <origin xyz="0.0 0.010593 -0.118037" rpy="0 0 0"/>
    <parent link="left_upper_leg"/>
    <child link="left_lower_leg"/>
    <axis xyz="-1.0 -0.0 1e-06"/>
    <limit upper="2.094395" lower="0.0" effort="100.0" velocity="100.0"/>
  </joint>
  <joint name="left_hip_pitch" type="revolute">
    <origin xyz="0.081889 -0.019342 -0.001625" rpy="0 0 0"/>
    <parent link="left_hip"/>
    <child link="left_upper_leg"/>
    <axis xyz="1.0 0.0 -1e-06"/>
    <limit upper="1.570796" lower="-1.570796" effort="100.0" velocity="100.0"/>
  </joint>
  <joint name="left_hip_roll" type="revolute">
    <origin xyz="0.004952 -0.006239 -0.060357" rpy="0 0 0"/>
    <parent link="left_hip_rotation"/>
    <child link="left_hip"/>
    <axis xyz="0.0 -0.99649 -0.083715"/>
    <limit upper="0.523599" lower="-0.523599" effort="100.0" velocity="100.0"/>
  </joint>
  <joint name="left_hip_yaw" type="revolute">
    <origin xyz="0.046212 -0.00171 0.022391" rpy="0 0 0"/>
    <parent link="base_link"/>
    <child link="left_hip_rotation"/>
    <axis xyz="-0.0 0.083715 -0.99649"/>
    <limit upper="0.436332" lower="-0.436332" effort="100.0" velocity="100.0"/>
  </joint>
  <joint name="right_ankle" type="revolute">
    <origin xyz="0.009466 0.000713 -0.137183" rpy="0 0 0"/>
    <parent link="right_lower_leg"/>
    <child link="right_foot"/>
    <axis xyz="-1.0 -0.0 0.0"/>
    <limit upper="1.22173" lower="-1.396263" effort="100.0" velocity="100.0"/>
  </joint>
  <joint name="right_knee" type="revolute">
    <origin xyz="0.0 0.010592 -0.118038" rpy="0 0 0"/>
    <parent link="right_upper_leg"/>
    <child link="right_lower_leg"/>
    <axis xyz="1.0 0.0 0.0"/>
    <limit upper="0.0" lower="-2.094395" effort="100.0" velocity="100.0"/>
  </joint>
  <joint name="right_hip_pitch" type="revolute">
    <origin xyz="-0.081888 -0.019342 -0.001625" rpy="0 0 0"/>
    <parent link="right_hip"/>
    <child link="right_upper_leg"/>
    <axis xyz="-1.0 -0.0 -0.0"/>
    <limit upper="1.570796" lower="-1.570796" effort="100.0" velocity="100.0"/>
  </joint>
  <joint name="right_hip_roll" type="revolute">
    <origin xyz="-0.004953 -0.006238 -0.060357" rpy="0 0 0"/>
    <parent link="right_hip_rotation"/>
    <child link="right_hip"/>
    <axis xyz="0.0 -0.99649 -0.083715"/>
    <limit upper="0.523599" lower="-0.523599" effort="100.0" velocity="100.0"/>
  </joint>
  <joint name="right_hip_yaw" type="revolute">
    <origin xyz="-0.046882 -0.001702 0.022392" rpy="0 0 0"/>
    <parent link="base_link"/>
    <child link="right_hip_rotation"/>
    <axis xyz="-0.0 0.083715 -0.99649"/>
    <limit upper="0.436332" lower="-0.436332" effort="100.0" velocity="100.0"/>
  </joint>
  <joint name="left_foot_pad" type="fixed">
    <origin xyz="-0.015026 0.063543 -0.056716" rpy="0 0 0"/>
    <parent link="left_foot"/>
    <child link="left_foot_pad"/>
    <axis xyz="0 0 0"/>
  </joint>
  <joint name="right_foot_pad" type="fixed">
    <origin xyz="0.015026 0.063543 -0.056716" rpy="0 0 0"/>
    <parent link="right_foot"/>
    <child link="right_foot_pad"/>
    <axis xyz="0 0 0"/>
  </joint>
</robot>
